Workbook

Sheet AUDIT-Q
B1: A U D I T C A T E G O R Y | C1: ='List of JPs'!B3 -> 0 | D1: ='List of JPs'!B4 -> 0 | E1: ='List of JPs'!B5 -> 0 | F1: ='List of JPs'!B6 -> 0 | G1: ='List of JPs'!B7 -> 0 | H1: ='List of JPs'!B8 -> 0 | I1: ='List of JPs'!B9 -> 0 | J1: ='List of JPs'!B10 -> 0 | K1: ='List of JPs'!B11 -> 0 | L1: ='List of JPs'!B12 -> 0 | M1: ='List of JPs'!B13 -> 0 | N1: ='List of JPs'!B14 -> 0 | O1: ='List of JPs'!B15 -> 0 | P1: ='List of JPs'!B16 -> 0 | Q1: ='List of JPs'!B17 -> 0 | R1: ='List of JPs'!B18 -> 0 | S1: ='List of JPs'!B19 -> 0 | T1: ='List of JPs'!B20 -> 0 | U1: ='List of JPs'!B21 -> 0 | V1: ='List of JPs'!B22 -> 0 | W1: ='List of JPs'!B23 -> 0 | X1: ='List of JPs'!B24 -> 0 | Y1: ='List of JPs'!B25 -> 0 | Z1: ='List of JPs'!B26 -> 0 | AA1: ='List of JPs'!B27 -> 0 | AB1: ='List of JPs'!B28 -> 0 | AC1: ='List of JPs'!B29 -> 0 | AD1: ='List of JPs'!B30 -> 0 | AE1: ='List of JPs'!B31 -> 0 | AF1: ='List of JPs'!B32 -> 0 | AG1: ='List of JPs'!B33 -> 0
B2: DEDAC
A3: 1.1 | B3: Is DEDAC available in Job Folder?
A4: 1.2 | B4: Is AFC JP available in Job Folder and uploaded to E1?
A5: 1.3 | B5: Does the rev of JP in the project folder corresponds to the rev of JP in E1?
A6: 1.4 | B6: Is the MOC number indicated in the header table of AFC JP in E1?
A7: 1.5 | B7: If MOC number is being indicated, is Functional Review Checklist included in the 5. Reviews, MOC job folder? Is documentation for this MOC record in MOC IT Tool Application on the Web? Is link to MOC IT Tool Application folder in 5. Reviews, MOC job folder?
A8: 1.6 | B8: Have all relevant boxes of DEDAC QAQC Checklist and Work Processes Checklist been completed. i.e. N/A is marked for questions not relevant to this Job Pack? Is the native file and pdf copy in the folder? Is the pdf copy dated before to engineer jp signature date?
A9: 1.7 | B9: If applicable, was a redlined and signed P&ID saved in job folder?
A10: 1.8 | B10: Does the JP Proposed Solution match what is actually being implemented?
A11: 1.11 | B11: Does new/modified piping design comply with all applicable TCO and Industry standards and regulations?
B12: Welding
A13: 2.1 | B13: Is generic WPS (specified on Piping ISO drawing(s) or Repair Plan?
A14: =+A13+0.1 -> 2.2 | B14: If the project involves API Line Pipe or Equipment other than Piping, is the WPS confirmation with MI documented in the project folder?
A15: =+A14+0.1 -> 2.3 | B15: If PWHT is required, are the PWHT requirements specified in the JP and noted on the Piping ISO/Repair Plan?
A16: =+A15+0.1 -> 2.4 | B16: Are NDE and hardness testing requirements specified to be completed AFTER PWHT?
A17: =+A16+0.1 -> 2.5 | B17: If project involves repairs or modifications to ASME or GOST pressure vessels with PWHT requirements, is the e-mail confirmation with the Reliability Lead Inspector and MI Specialist saved in the project folder?
A18: =+A17+0.1 -> 2.6 | B18: Is engineered PWHT procedure (e.g. for modified GOST/ASME vessel) included in the JP?
A19: =+A18+0.1 -> 2.7 | B19: Is hydrogen bake-out required?
A20: =+A19+0.1 -> 2.8 | B20: Is hydrogen bake-out specified prior to welding?
A21: 2.9 | B21: Is the e-mail that contains consultation with MI group for hydrogen bake-out questions (regarding piping repairs/modifications) saved in the project folder?
A22: 2.1 | B22: Has Thermal Stress due to PWHT/H2Bake-out on installed Piping or Equipment been considered? Were any connected Piping, Attachments or Restraints specified to be removed/disconnected? Were Dead Weight Supports added to sustain Structural Integrity? Has this been noted in the Procedure?
B23: Hot Tap
A24: 3.1 | B24: Are the words "Hot Tap" included in the title of JP and the copy of hot tap permit (orange sheet) included in the Job Pack?
A25: 3.2 | B25: Does the Job Pack comply with the requirements of SI-121 Hot Tapping?
A26: 3.3 | B26: Is the hydrotest calculation in Excel format for hot tapping included in the Job Folder and PDF format included in the Job Pack?
A27: 3.4 | B27: Can it be demonstrated that all other options, to Hot Tapping or Stoppling, have been exhausted? This includes deferring the work till the next Facility Turnaround/Shutdown.
A28: 3.5 | B28: Does the Job Pack include a scanned copy of the SI-121 Checklist with Part 1 duly signed off by the responsible Design Engineer (Project Engineer)?
A29: 3.6 | B29: Stoppling Job Pack shall also include (apart from everything else required as per SI-121): a) Stoppling Material List, b) Stoppling Schematic and c) Stoppling Contractor Method Statement. Is JP complete?
A30: 3.7 | B30: Has Operations' Emergency Procedure, for abandoning a Hot Tap or Stopple been prepared, fully signed off and attached to the Job Pack?
B31: NDE
A32: 4.1 | B32: Is the right type and % of NDE specified (i.e. 5% PT/MT, 100% RT, 100% VT)?
A33: 4.2 | B33: If there is more than one pipe class, are NDE requirements listed separately for each pipe class?
A34: 4.3 | B34: If the project involves equipment other than piping, are NDE requirements confirmed by the Reliability Lead Inspector documented in the job folder?
A35: 4.4 | B35: If Welding of New Pipe to Existing Pipe Required, are instructions noted in the Job Pack to perform NDE at the proposed tie-in point prior to beginning mechanical work? Is a note about requirement to perform NDE included on the ISO drawing?
B36: Golden Weld (Closure Weld)
B37: Are the following documents attached to the Request?
A38: 5.1 | B38: · P&ID and / or Isometric drawing with the Golden Weld(s) clearly identified.
A39: 5.2 | B39: · Inspection and Test Plan
A40: 5.3 | B40: · Weld Procedure and Procedure Qualification Record
...

Sheet Criteria
B2: NA | C2: Not Applicable
B3: 0 – No Issues | C3: No issues
B4: 1 – Design | C4: Design issue: examples wrong WPS, does not comply with standard, etc.
B5: 2 – Documentation | C5: Documentation issue: DEDAC, e-mails, files, etc. are missing in the project folder
B6: 3 – Incomplete | C6: Not enough information is available or too difficult to assess and answer the question
B7: 4 – Error | C7: Technical or human errors, omissions made by engineer like omitting important steps in procedure, not marking boxes properly (missing "N/A"'s)

Sheet RESULTS
B1: A U D I T C A T E G O R Y | C1: =Criteria!B2 -> NA | D1: =Criteria!B3 -> 0 – No Issues | E1: =Criteria!B4 -> 1 – Design | F1: =Criteria!B5 -> 2 – Documentation | G1: =Criteria!B6 -> 3 – Incomplete | H1: =Criteria!B7 -> 4 – Error
A2: 1 | B2: DEDAC | C2: =SUM(C3:C11) -> 0 | D2: =SUM(D3:D11) -> 0 | E2: =SUM(E3:E11) -> 0 | F2: =SUM(F3:F11) -> 0 | G2: =SUM(G3:G11) -> 0 | H2: =SUM(H3:H11) -> 0
A3: 1.1 | B3: Is DEDAC available in Job Folder? | C3: =IF('AUDIT-Q'!$C3=0,"",COUNTIF('AUDIT-Q'!$C3:$J3,RESULTS!C$1)) | D3: =IF('AUDIT-Q'!$C3=0,"",COUNTIF('AUDIT-Q'!$C3:$J3,RESULTS!D$1)) | E3: =IF('AUDIT-Q'!$C3=0,"",COUNTIF('AUDIT-Q'!$C3:$J3,RESULTS!E$1)) | F3: =IF('AUDIT-Q'!$C3=0,"",COUNTIF('AUDIT-Q'!$C3:$J3,RESULTS!F$1)) | G3: =IF('AUDIT-Q'!$C3=0,"",COUNTIF('AUDIT-Q'!$C3:$J3,RESULTS!G$1)) | H3: =IF('AUDIT-Q'!$C3=0,"",COUNTIF('AUDIT-Q'!$C3:$J3,RESULTS!H$1))
A4: 1.2 | B4: Is AFC JP available in Job Folder and uploaded to E1? | C4: =IF('AUDIT-Q'!$C4=0,"",COUNTIF('AUDIT-Q'!$C4:$J4,RESULTS!C$1)) | D4: =IF('AUDIT-Q'!$C4=0,"",COUNTIF('AUDIT-Q'!$C4:$J4,RESULTS!D$1)) | E4: =IF('AUDIT-Q'!$C4=0,"",COUNTIF('AUDIT-Q'!$C4:$J4,RESULTS!E$1)) | F4: =IF('AUDIT-Q'!$C4=0,"",COUNTIF('AUDIT-Q'!$C4:$J4,RESULTS!F$1)) | G4: =IF('AUDIT-Q'!$C4=0,"",COUNTIF('AUDIT-Q'!$C4:$J4,RESULTS!G$1)) | H4: =IF('AUDIT-Q'!$C4=0,"",COUNTIF('AUDIT-Q'!$C4:$J4,RESULTS!H$1))
A5: 1.3 | B5: Do all drawings have the same revision number as the Job Pack uploaded in E1? | C5: =IF('AUDIT-Q'!$C5=0,"",COUNTIF('AUDIT-Q'!$C5:$J5,RESULTS!C$1)) | D5: =IF('AUDIT-Q'!$C5=0,"",COUNTIF('AUDIT-Q'!$C5:$J5,RESULTS!D$1)) | E5: =IF('AUDIT-Q'!$C5=0,"",COUNTIF('AUDIT-Q'!$C5:$J5,RESULTS!E$1)) | F5: =IF('AUDIT-Q'!$C5=0,"",COUNTIF('AUDIT-Q'!$C5:$J5,RESULTS!F$1)) | G5: =IF('AUDIT-Q'!$C5=0,"",COUNTIF('AUDIT-Q'!$C5:$J5,RESULTS!G$1)) | H5: =IF('AUDIT-Q'!$C5=0,"",COUNTIF('AUDIT-Q'!$C5:$J5,RESULTS!H$1))
A6: 1.4 | B6: Is the MOC number indicated in the header table of AFC JP in E1? | C6: =IF('AUDIT-Q'!$C6=0,"",COUNTIF('AUDIT-Q'!$C6:$J6,RESULTS!C$1)) | D6: =IF('AUDIT-Q'!$C6=0,"",COUNTIF('AUDIT-Q'!$C6:$J6,RESULTS!D$1)) | E6: =IF('AUDIT-Q'!$C6=0,"",COUNTIF('AUDIT-Q'!$C6:$J6,RESULTS!E$1)) | F6: =IF('AUDIT-Q'!$C6=0,"",COUNTIF('AUDIT-Q'!$C6:$J6,RESULTS!F$1)) | G6: =IF('AUDIT-Q'!$C6=0,"",COUNTIF('AUDIT-Q'!$C6:$J6,RESULTS!G$1)) | H6: =IF('AUDIT-Q'!$C6=0,"",COUNTIF('AUDIT-Q'!$C6:$J6,RESULTS!H$1))
A7: 1.5 | B7: If MOC number is being indicated, is the PHA/HAZOP documentation included in the job folder? Check documentation for this MOC record in MOC IT Tool Application on the Web. | C7: =IF('AUDIT-Q'!$C7=0,"",COUNTIF('AUDIT-Q'!$C7:$J7,RESULTS!C$1)) | D7: =IF('AUDIT-Q'!$C7=0,"",COUNTIF('AUDIT-Q'!$C7:$J7,RESULTS!D$1)) | E7: =IF('AUDIT-Q'!$C7=0,"",COUNTIF('AUDIT-Q'!$C7:$J7,RESULTS!E$1)) | F7: =IF('AUDIT-Q'!$C7=0,"",COUNTIF('AUDIT-Q'!$C7:$J7,RESULTS!F$1)) | G7: =IF('AUDIT-Q'!$C7=0,"",COUNTIF('AUDIT-Q'!$C7:$J7,RESULTS!G$1)) | H7: =IF('AUDIT-Q'!$C7=0,"",COUNTIF('AUDIT-Q'!$C7:$J7,RESULTS!H$1))
A8: 1.6 | B8: Have all relevant boxes of DEDAC been completed. i.e. N/A is marked for questions not relevant to this Job Pack? | C8: =IF('AUDIT-Q'!$C8=0,"",COUNTIF('AUDIT-Q'!$C8:$J8,RESULTS!C$1)) | D8: =IF('AUDIT-Q'!$C8=0,"",COUNTIF('AUDIT-Q'!$C8:$J8,RESULTS!D$1)) | E8: =IF('AUDIT-Q'!$C8=0,"",COUNTIF('AUDIT-Q'!$C8:$J8,RESULTS!E$1)) | F8: =IF('AUDIT-Q'!$C8=0,"",COUNTIF('AUDIT-Q'!$C8:$J8,RESULTS!F$1)) | G8: =IF('AUDIT-Q'!$C8=0,"",COUNTIF('AUDIT-Q'!$C8:$J8,RESULTS!G$1)) | H8: =IF('AUDIT-Q'!$C8=0,"",COUNTIF('AUDIT-Q'!$C8:$J8,RESULTS!H$1))
A9: 1.7 | B9: If applicable, was a redlined and signed project P&ID saved in job folder? | C9: =IF('AUDIT-Q'!$C9=0,"",COUNTIF('AUDIT-Q'!$C9:$J9,RESULTS!C$1)) | D9: =IF('AUDIT-Q'!$C9=0,"",COUNTIF('AUDIT-Q'!$C9:$J9,RESULTS!D$1)) | E9: =IF('AUDIT-Q'!$C9=0,"",COUNTIF('AUDIT-Q'!$C9:$J9,RESULTS!E$1)) | F9: =IF('AUDIT-Q'!$C9=0,"",COUNTIF('AUDIT-Q'!$C9:$J9,RESULTS!F$1)) | G9: =IF('AUDIT-Q'!$C9=0,"",COUNTIF('AUDIT-Q'!$C9:$J9,RESULTS!G$1)) | H9: =IF('AUDIT-Q'!$C9=0,"",COUNTIF('AUDIT-Q'!$C9:$J9,RESULTS!H$1))
A10: 1.8 | B10: Does the JP Proposed Solution match what is actually being implemented? | C10: =IF('AUDIT-Q'!$C10=0,"",COUNTIF('AUDIT-Q'!$C10:$J10,RESULTS!C$1)) | D10: =IF('AUDIT-Q'!$C10=0,"",COUNTIF('AUDIT-Q'!$C10:$J10,RESULTS!D$1)) | E10: =IF('AUDIT-Q'!$C10=0,"",COUNTIF('AUDIT-Q'!$C10:$J10,RESULTS!E$1)) | F10: =IF('AUDIT-Q'!$C10=0,"",COUNTIF('AUDIT-Q'!$C10:$J10,RESULTS!F$1)) | G10: =IF('AUDIT-Q'!$C10=0,"",COUNTIF('AUDIT-Q'!$C10:$J10,RESULTS!G$1)) | H10: =IF('AUDIT-Q'!$C10=0,"",COUNTIF('AUDIT-Q'!$C10:$J10,RESULTS!H$1))
A11: 1.11 | B11: Does new/modified piping design comply with all applicable TCO and Industry standards and regulations? | C11: =IF('AUDIT-Q'!$C11=0,"",COUNTIF('AUDIT-Q'!$C11:$J11,RESULTS!C$1)) | D11: =IF('AUDIT-Q'!$C11=0,"",COUNTIF('AUDIT-Q'!$C11:$J11,RESULTS!D$1)) | E11: =IF('AUDIT-Q'!$C11=0,"",COUNTIF('AUDIT-Q'!$C11:$J11,RESULTS!E$1)) | F11: =IF('AUDIT-Q'!$C11=0,"",COUNTIF('AUDIT-Q'!$C11:$J11,RESULTS!F$1)) | G11: =IF('AUDIT-Q'!$C11=0,"",COUNTIF('AUDIT-Q'!$C11:$J11,RESULTS!G$1)) | H11: =IF('AUDIT-Q'!$C11=0,"",COUNTIF('AUDIT-Q'!$C11:$J11,RESULTS!H$1))
A12: 2 | B12: Welding | C12: =SUM(C13:C25) -> #REF! | D12: =SUM(D13:D25) -> #REF! | E12: =SUM(E13:E25) -> #REF! | F12: =SUM(F13:F25) -> #REF! | G12: =SUM(G13:G25) -> #REF! | H12: =SUM(H13:H25) -> #REF!
A13: 2.1 | B13: Is the right Weld Procedure Specification (WPS) specified? | C13: =IF('AUDIT-Q'!#REF!=0,"",COUNTIF('AUDIT-Q'!#REF!,RESULTS!C$1)) -> #REF! | D13: =IF('AUDIT-Q'!#REF!=0,"",COUNTIF('AUDIT-Q'!#REF!,RESULTS!D$1)) -> #REF! | E13: =IF('AUDIT-Q'!#REF!=0,"",COUNTIF('AUDIT-Q'!#REF!,RESULTS!E$1)) -> #REF! | F13: =IF('AUDIT-Q'!#REF!=0,"",COUNTIF('AUDIT-Q'!#REF!,RESULTS!F$1)) -> #REF! | G13: =IF('AUDIT-Q'!#REF!=0,"",COUNTIF('AUDIT-Q'!#REF!,RESULTS!G$1)) -> #REF! | H13: =IF('AUDIT-Q'!#REF!=0,"",COUNTIF('AUDIT-Q'!#REF!,RESULTS!H$1)) -> #REF!
A14: 2.2 | B14: Is WPS specified in the JP Description of Work and Piping ISO drawing(s) or Repair Plan? | C14: =IF('AUDIT-Q'!$C13=0,"",COUNTIF('AUDIT-Q'!$C13:$J13,RESULTS!C$1)) | D14: =IF('AUDIT-Q'!$C13=0,"",COUNTIF('AUDIT-Q'!$C13:$J13,RESULTS!D$1)) | E14: =IF('AUDIT-Q'!$C13=0,"",COUNTIF('AUDIT-Q'!$C13:$J13,RESULTS!E$1)) | F14: =IF('AUDIT-Q'!$C13=0,"",COUNTIF('AUDIT-Q'!$C13:$J13,RESULTS!F$1)) | G14: =IF('AUDIT-Q'!$C13=0,"",COUNTIF('AUDIT-Q'!$C13:$J13,RESULTS!G$1)) | H14: =IF('AUDIT-Q'!$C13=0,"",COUNTIF('AUDIT-Q'!$C13:$J13,RESULTS!H$1))
A15: 2.3 | B15: Is a copy of the WPS included in the JP? | C15: =IF('AUDIT-Q'!#REF!=0,"",COUNTIF('AUDIT-Q'!#REF!,RESULTS!C$1)) -> #REF! | D15: =IF('AUDIT-Q'!#REF!=0,"",COUNTIF('AUDIT-Q'!#REF!,RESULTS!D$1)) -> #REF! | E15: =IF('AUDIT-Q'!#REF!=0,"",COUNTIF('AUDIT-Q'!#REF!,RESULTS!E$1)) -> #REF! | F15: =IF('AUDIT-Q'!#REF!=0,"",COUNTIF('AUDIT-Q'!#REF!,RESULTS!F$1)) -> #REF! | G15: =IF('AUDIT-Q'!#REF!=0,"",COUNTIF('AUDIT-Q'!#REF!,RESULTS!G$1)) -> #REF! | H15: =IF('AUDIT-Q'!#REF!=0,"",COUNTIF('AUDIT-Q'!#REF!,RESULTS!H$1)) -> #REF!
A16: 2.4 | B16: If the project involves API Line Pipe or Equipment other than Piping, is the WPS confirmation with MI documented in the project folder? | C16: =IF('AUDIT-Q'!$C14=0,"",COUNTIF('AUDIT-Q'!$C14:$J14,RESULTS!C$1)) | D16: =IF('AUDIT-Q'!$C14=0,"",COUNTIF('AUDIT-Q'!$C14:$J14,RESULTS!D$1)) | E16: =IF('AUDIT-Q'!$C14=0,"",COUNTIF('AUDIT-Q'!$C14:$J14,RESULTS!E$1)) | F16: =IF('AUDIT-Q'!$C14=0,"",COUNTIF('AUDIT-Q'!$C14:$J14,RESULTS!F$1)) | G16: =IF('AUDIT-Q'!$C14=0,"",COUNTIF('AUDIT-Q'!$C14:$J14,RESULTS!G$1)) | H16: =IF('AUDIT-Q'!$C14=0,"",COUNTIF('AUDIT-Q'!$C14:$J14,RESULTS!H$1))
A17: 2.5 | B17: If there is no TCO-approved procedure available, is Contractor-qualified WPS developed? Has the WPS and PQR been fully signed off by the Contractor and approved by MI? | C17: =IF('AUDIT-Q'!#REF!=0,"",COUNTIF('AUDIT-Q'!#REF!,RESULTS!C$1)) -> #REF! | D17: =IF('AUDIT-Q'!#REF!=0,"",COUNTIF('AUDIT-Q'!#REF!,RESULTS!D$1)) -> #REF! | E17: =IF('AUDIT-Q'!#REF!=0,"",COUNTIF('AUDIT-Q'!#REF!,RESULTS!E$1)) -> #REF! | F17: =IF('AUDIT-Q'!#REF!=0,"",COUNTIF('AUDIT-Q'!#REF!,RESULTS!F$1)) -> #REF! | G17: =IF('AUDIT-Q'!#REF!=0,"",COUNTIF('AUDIT-Q'!#REF!,RESULTS!G$1)) -> #REF! | H17: =IF('AUDIT-Q'!#REF!=0,"",COUNTIF('AUDIT-Q'!#REF!,RESULTS!H$1)) -> #REF!
A18: 2.6 | B18: If PWHT is required, are the PWHT requirements specified in the JP and noted on the Piping ISO/Repair Plan? | C18: =IF('AUDIT-Q'!$C15=0,"",COUNTIF('AUDIT-Q'!$C15:$J15,RESULTS!C$1)) | D18: =IF('AUDIT-Q'!$C15=0,"",COUNTIF('AUDIT-Q'!$C15:$J15,RESULTS!D$1)) | E18: =IF('AUDIT-Q'!$C15=0,"",COUNTIF('AUDIT-Q'!$C15:$J15,RESULTS!E$1)) | F18: =IF('AUDIT-Q'!$C15=0,"",COUNTIF('AUDIT-Q'!$C15:$J15,RESULTS!F$1)) | G18: =IF('AUDIT-Q'!$C15=0,"",COUNTIF('AUDIT-Q'!$C15:$J15,RESULTS!G$1)) | H18: =IF('AUDIT-Q'!$C15=0,"",COUNTIF('AUDIT-Q'!$C15:$J15,RESULTS!H$1))
A19: 2.7 | B19: Are NDE and hardness testing requirements specified to be completed AFTER PWHT? | C19: =IF('AUDIT-Q'!$C16=0,"",COUNTIF('AUDIT-Q'!$C16:$J16,RESULTS!C$1)) | D19: =IF('AUDIT-Q'!$C16=0,"",COUNTIF('AUDIT-Q'!$C16:$J16,RESULTS!D$1)) | E19: =IF('AUDIT-Q'!$C16=0,"",COUNTIF('AUDIT-Q'!$C16:$J16,RESULTS!E$1)) | F19: =IF('AUDIT-Q'!$C16=0,"",COUNTIF('AUDIT-Q'!$C16:$J16,RESULTS!F$1)) | G19: =IF('AUDIT-Q'!$C16=0,"",COUNTIF('AUDIT-Q'!$C16:$J16,RESULTS!G$1)) | H19: =IF('AUDIT-Q'!$C16=0,"",COUNTIF('AUDIT-Q'!$C16:$J16,RESULTS!H$1))
A20: 2.8 | B20: If project involves repairs or modifications to ASME or GOST pressure vessels with PWHT requirements, is the e-mail confirmation with the Reliability Lead Inspector and MI Specialist saved in the project folder? | C20: =IF('AUDIT-Q'!$C17=0,"",COUNTIF('AUDIT-Q'!$C17:$J17,RESULTS!C$1)) | D20: =IF('AUDIT-Q'!$C17=0,"",COUNTIF('AUDIT-Q'!$C17:$J17,RESULTS!D$1)) | E20: =IF('AUDIT-Q'!$C17=0,"",COUNTIF('AUDIT-Q'!$C17:$J17,RESULTS!E$1)) | F20: =IF('AUDIT-Q'!$C17=0,"",COUNTIF('AUDIT-Q'!$C17:$J17,RESULTS!F$1)) | G20: =IF('AUDIT-Q'!$C17=0,"",COUNTIF('AUDIT-Q'!$C17:$J17,RESULTS!G$1)) | H20: =IF('AUDIT-Q'!$C17=0,"",COUNTIF('AUDIT-Q'!$C17:$J17,RESULTS!H$1))
A21: 2.9 | B21: Is engineered PWHT procedure (e.g. for modified GOST/ASME vessel) included in the JP? | C21: =IF('AUDIT-Q'!$C18=0,"",COUNTIF('AUDIT-Q'!$C18:$J18,RESULTS!C$1)) | D21: =IF('AUDIT-Q'!$C18=0,"",COUNTIF('AUDIT-Q'!$C18:$J18,RESULTS!D$1)) | E21: =IF('AUDIT-Q'!$C18=0,"",COUNTIF('AUDIT-Q'!$C18:$J18,RESULTS!E$1)) | F21: =IF('AUDIT-Q'!$C18=0,"",COUNTIF('AUDIT-Q'!$C18:$J18,RESULTS!F$1)) | G21: =IF('AUDIT-Q'!$C18=0,"",COUNTIF('AUDIT-Q'!$C18:$J18,RESULTS!G$1)) | H21: =IF('AUDIT-Q'!$C18=0,"",COUNTIF('AUDIT-Q'!$C18:$J18,RESULTS!H$1))
A22: 2.1 | B22: Is hydrogen bake-out required? | C22: =IF('AUDIT-Q'!$C19=0,"",COUNTIF('AUDIT-Q'!$C19:$J19,RESULTS!C$1)) | D22: =IF('AUDIT-Q'!$C19=0,"",COUNTIF('AUDIT-Q'!$C19:$J19,RESULTS!D$1)) | E22: =IF('AUDIT-Q'!$C19=0,"",COUNTIF('AUDIT-Q'!$C19:$J19,RESULTS!E$1)) | F22: =IF('AUDIT-Q'!$C19=0,"",COUNTIF('AUDIT-Q'!$C19:$J19,RESULTS!F$1)) | G22: =IF('AUDIT-Q'!$C19=0,"",COUNTIF('AUDIT-Q'!$C19:$J19,RESULTS!G$1)) | H22: =IF('AUDIT-Q'!$C19=0,"",COUNTIF('AUDIT-Q'!$C19:$J19,RESULTS!H$1))
A23: 2.11 | B23: Is hydrogen bake-out specified prior to welding? | C23: =IF('AUDIT-Q'!$C20=0,"",COUNTIF('AUDIT-Q'!$C20:$J20,RESULTS!C$1)) | D23: =IF('AUDIT-Q'!$C20=0,"",COUNTIF('AUDIT-Q'!$C20:$J20,RESULTS!D$1)) | E23: =IF('AUDIT-Q'!$C20=0,"",COUNTIF('AUDIT-Q'!$C20:$J20,RESULTS!E$1)) | F23: =IF('AUDIT-Q'!$C20=0,"",COUNTIF('AUDIT-Q'!$C20:$J20,RESULTS!F$1)) | G23: =IF('AUDIT-Q'!$C20=0,"",COUNTIF('AUDIT-Q'!$C20:$J20,RESULTS!G$1)) | H23: =IF('AUDIT-Q'!$C20=0,"",COUNTIF('AUDIT-Q'!$C20:$J20,RESULTS!H$1))
A24: 2.12 | B24: Is the e-mail that contains consultation with MI group for hydrogen bake-out questions (regarding piping repairs/modifications) saved in the project folder? | C24: =IF('AUDIT-Q'!$C21=0,"",COUNTIF('AUDIT-Q'!$C21:$J21,RESULTS!C$1)) | D24: =IF('AUDIT-Q'!$C21=0,"",COUNTIF('AUDIT-Q'!$C21:$J21,RESULTS!D$1)) | E24: =IF('AUDIT-Q'!$C21=0,"",COUNTIF('AUDIT-Q'!$C21:$J21,RESULTS!E$1)) | F24: =IF('AUDIT-Q'!$C21=0,"",COUNTIF('AUDIT-Q'!$C21:$J21,RESULTS!F$1)) | G24: =IF('AUDIT-Q'!$C21=0,"",COUNTIF('AUDIT-Q'!$C21:$J21,RESULTS!G$1)) | H24: =IF('AUDIT-Q'!$C21=0,"",COUNTIF('AUDIT-Q'!$C21:$J21,RESULTS!H$1))
A25: 2.13 | B25: Has Thermal Stress due to PWHT/H2Bake-out on installed Piping or Equipment been considered? Were any connected Piping, Attachments or Restraints specified to be removed/disconnected? Were Dead Weight Supports added to sustain Structural Integrity? Has this been noted in the Procedure? | C25: =IF('AUDIT-Q'!$C22=0,"",COUNTIF('AUDIT-Q'!$C22:$J22,RESULTS!C$1)) | D25: =IF('AUDIT-Q'!$C22=0,"",COUNTIF('AUDIT-Q'!$C22:$J22,RESULTS!D$1)) | E25: =IF('AUDIT-Q'!$C22=0,"",COUNTIF('AUDIT-Q'!$C22:$J22,RESULTS!E$1)) | F25: =IF('AUDIT-Q'!$C22=0,"",COUNTIF('AUDIT-Q'!$C22:$J22,RESULTS!F$1)) | G25: =IF('AUDIT-Q'!$C22=0,"",COUNTIF('AUDIT-Q'!$C22:$J22,RESULTS!G$1)) | H25: =IF('AUDIT-Q'!$C22=0,"",COUNTIF('AUDIT-Q'!$C22:$J22,RESULTS!H$1))
A26: 3 | B26: Hot Tap | C26: =SUM(C27:C33) -> 0 | D26: =SUM(D27:D33) -> 0 | E26: =SUM(E27:E33) -> 0 | F26: =SUM(F27:F33) -> 0 | G26: =SUM(G27:G33) -> 0 | H26: =SUM(H27:H33) -> 0
A27: 3.1 | B27: Are the words "Hot Tap" included in the title of JP and the copy of hot tap permit (orange sheet) included in the Job Pack? | C27: =IF('AUDIT-Q'!$C24=0,"",COUNTIF('AUDIT-Q'!$C24:$J24,RESULTS!C$1)) | D27: =IF('AUDIT-Q'!$C24=0,"",COUNTIF('AUDIT-Q'!$C24:$J24,RESULTS!D$1)) | E27: =IF('AUDIT-Q'!$C24=0,"",COUNTIF('AUDIT-Q'!$C24:$J24,RESULTS!E$1)) | F27: =IF('AUDIT-Q'!$C24=0,"",COUNTIF('AUDIT-Q'!$C24:$J24,RESULTS!F$1)) | G27: =IF('AUDIT-Q'!$C24=0,"",COUNTIF('AUDIT-Q'!$C24:$J24,RESULTS!G$1)) | H27: =IF('AUDIT-Q'!$C24=0,"",COUNTIF('AUDIT-Q'!$C24:$J24,RESULTS!H$1))
A28: 3.2 | B28: Does the Job Pack comply with the requirements of SI-121 Hot Tapping? | C28: =IF('AUDIT-Q'!$C25=0,"",COUNTIF('AUDIT-Q'!$C25:$J25,RESULTS!C$1)) | D28: =IF('AUDIT-Q'!$C25=0,"",COUNTIF('AUDIT-Q'!$C25:$J25,RESULTS!D$1)) | E28: =IF('AUDIT-Q'!$C25=0,"",COUNTIF('AUDIT-Q'!$C25:$J25,RESULTS!E$1)) | F28: =IF('AUDIT-Q'!$C25=0,"",COUNTIF('AUDIT-Q'!$C25:$J25,RESULTS!F$1)) | G28: =IF('AUDIT-Q'!$C25=0,"",COUNTIF('AUDIT-Q'!$C25:$J25,RESULTS!G$1)) | H28: =IF('AUDIT-Q'!$C25=0,"",COUNTIF('AUDIT-Q'!$C25:$J25,RESULTS!H$1))
A29: 3.3 | B29: Is the hydrotest calculation in Excel format for hot tapping included in the Job Folder and PDF format included in the Job Pack? | C29: =IF('AUDIT-Q'!$C26=0,"",COUNTIF('AUDIT-Q'!$C26:$J26,RESULTS!C$1)) | D29: =IF('AUDIT-Q'!$C26=0,"",COUNTIF('AUDIT-Q'!$C26:$J26,RESULTS!D$1)) | E29: =IF('AUDIT-Q'!$C26=0,"",COUNTIF('AUDIT-Q'!$C26:$J26,RESULTS!E$1)) | F29: =IF('AUDIT-Q'!$C26=0,"",COUNTIF('AUDIT-Q'!$C26:$J26,RESULTS!F$1)) | G29: =IF('AUDIT-Q'!$C26=0,"",COUNTIF('AUDIT-Q'!$C26:$J26,RESULTS!G$1)) | H29: =IF('AUDIT-Q'!$C26=0,"",COUNTIF('AUDIT-Q'!$C26:$J26,RESULTS!H$1))
A30: 3.4 | B30: Can it be demonstrated that all other options, to Hot Tapping or Stoppling, have been exhausted? This includes deferring the work till the next Facility Turnaround/Shutdown. | C30: =IF('AUDIT-Q'!$C27=0,"",COUNTIF('AUDIT-Q'!$C27:$J27,RESULTS!C$1)) | D30: =IF('AUDIT-Q'!$C27=0,"",COUNTIF('AUDIT-Q'!$C27:$J27,RESULTS!D$1)) | E30: =IF('AUDIT-Q'!$C27=0,"",COUNTIF('AUDIT-Q'!$C27:$J27,RESULTS!E$1)) | F30: =IF('AUDIT-Q'!$C27=0,"",COUNTIF('AUDIT-Q'!$C27:$J27,RESULTS!F$1)) | G30: =IF('AUDIT-Q'!$C27=0,"",COUNTIF('AUDIT-Q'!$C27:$J27,RESULTS!G$1)) | H30: =IF('AUDIT-Q'!$C27=0,"",COUNTIF('AUDIT-Q'!$C27:$J27,RESULTS!H$1))
A31: 3.5 | B31: Does the Job Pack include a scanned copy of the SI-121 Checklist with Part 1 duly signed off by the responsible Design Engineer (Project Engineer)? | C31: =IF('AUDIT-Q'!$C28=0,"",COUNTIF('AUDIT-Q'!$C28:$J28,RESULTS!C$1)) | D31: =IF('AUDIT-Q'!$C28=0,"",COUNTIF('AUDIT-Q'!$C28:$J28,RESULTS!D$1)) | E31: =IF('AUDIT-Q'!$C28=0,"",COUNTIF('AUDIT-Q'!$C28:$J28,RESULTS!E$1)) | F31: =IF('AUDIT-Q'!$C28=0,"",COUNTIF('AUDIT-Q'!$C28:$J28,RESULTS!F$1)) | G31: =IF('AUDIT-Q'!$C28=0,"",COUNTIF('AUDIT-Q'!$C28:$J28,RESULTS!G$1)) | H31: =IF('AUDIT-Q'!$C28=0,"",COUNTIF('AUDIT-Q'!$C28:$J28,RESULTS!H$1))
A32: 3.6 | B32: Stoppling Job Pack shall also include (apart from everything else required as per SI-121): a) Stoppling Material List, b) Stoppling Schematic and c) Stoppling Contractor Method Statement. Is JP complete? | C32: =IF('AUDIT-Q'!$C29=0,"",COUNTIF('AUDIT-Q'!$C29:$J29,RESULTS!C$1)) | D32: =IF('AUDIT-Q'!$C29=0,"",COUNTIF('AUDIT-Q'!$C29:$J29,RESULTS!D$1)) | E32: =IF('AUDIT-Q'!$C29=0,"",COUNTIF('AUDIT-Q'!$C29:$J29,RESULTS!E$1)) | F32: =IF('AUDIT-Q'!$C29=0,"",COUNTIF('AUDIT-Q'!$C29:$J29,RESULTS!F$1)) | G32: =IF('AUDIT-Q'!$C29=0,"",COUNTIF('AUDIT-Q'!$C29:$J29,RESULTS!G$1)) | H32: =IF('AUDIT-Q'!$C29=0,"",COUNTIF('AUDIT-Q'!$C29:$J29,RESULTS!H$1))
A33: 3.7 | B33: Has Operations' Emergency Procedure, for abandoning a Hot Tap or Stopple been prepared, fully signed off and attached to the Job Pack? | C33: =IF('AUDIT-Q'!$C30=0,"",COUNTIF('AUDIT-Q'!$C30:$J30,RESULTS!C$1)) | D33: =IF('AUDIT-Q'!$C30=0,"",COUNTIF('AUDIT-Q'!$C30:$J30,RESULTS!D$1)) | E33: =IF('AUDIT-Q'!$C30=0,"",COUNTIF('AUDIT-Q'!$C30:$J30,RESULTS!E$1)) | F33: =IF('AUDIT-Q'!$C30=0,"",COUNTIF('AUDIT-Q'!$C30:$J30,RESULTS!F$1)) | G33: =IF('AUDIT-Q'!$C30=0,"",COUNTIF('AUDIT-Q'!$C30:$J30,RESULTS!G$1)) | H33: =IF('AUDIT-Q'!$C30=0,"",COUNTIF('AUDIT-Q'!$C30:$J30,RESULTS!H$1))
A34: 4 | B34: NDE | C34: =SUM(C35:C38) -> 0 | D34: =SUM(D35:D38) -> 0 | E34: =SUM(E35:E38) -> 0 | F34: =SUM(F35:F38) -> 0 | G34: =SUM(G35:G38) -> 0 | H34: =SUM(H35:H38) -> 0
A35: 4.1 | B35: Is the right type and % of NDE specified (i.e. 5% PT/MT, 100% RT, 100% VT)? | C35: =IF('AUDIT-Q'!$C32=0,"",COUNTIF('AUDIT-Q'!$C32:$J32,RESULTS!C$1)) | D35: =IF('AUDIT-Q'!$C32=0,"",COUNTIF('AUDIT-Q'!$C32:$J32,RESULTS!D$1)) | E35: =IF('AUDIT-Q'!$C32=0,"",COUNTIF('AUDIT-Q'!$C32:$J32,RESULTS!E$1)) | F35: =IF('AUDIT-Q'!$C32=0,"",COUNTIF('AUDIT-Q'!$C32:$J32,RESULTS!F$1)) | G35: =IF('AUDIT-Q'!$C32=0,"",COUNTIF('AUDIT-Q'!$C32:$J32,RESULTS!G$1)) | H35: =IF('AUDIT-Q'!$C32=0,"",COUNTIF('AUDIT-Q'!$C32:$J32,RESULTS!H$1))
A36: 4.2 | B36: If there is more than one pipe class, are NDE requirements listed separately for each pipe class? | C36: =IF('AUDIT-Q'!$C33=0,"",COUNTIF('AUDIT-Q'!$C33:$J33,RESULTS!C$1)) | D36: =IF('AUDIT-Q'!$C33=0,"",COUNTIF('AUDIT-Q'!$C33:$J33,RESULTS!D$1)) | E36: =IF('AUDIT-Q'!$C33=0,"",COUNTIF('AUDIT-Q'!$C33:$J33,RESULTS!E$1)) | F36: =IF('AUDIT-Q'!$C33=0,"",COUNTIF('AUDIT-Q'!$C33:$J33,RESULTS!F$1)) | G36: =IF('AUDIT-Q'!$C33=0,"",COUNTIF('AUDIT-Q'!$C33:$J33,RESULTS!G$1)) | H36: =IF('AUDIT-Q'!$C33=0,"",COUNTIF('AUDIT-Q'!$C33:$J33,RESULTS!H$1))
A37: 4.3 | B37: If the project involves equipment other than piping, are NDE requirements confirmed by the Reliability Lead Inspector documented in the job folder? | C37: =IF('AUDIT-Q'!$C34=0,"",COUNTIF('AUDIT-Q'!$C34:$J34,RESULTS!C$1)) | D37: =IF('AUDIT-Q'!$C34=0,"",COUNTIF('AUDIT-Q'!$C34:$J34,RESULTS!D$1)) | E37: =IF('AUDIT-Q'!$C34=0,"",COUNTIF('AUDIT-Q'!$C34:$J34,RESULTS!E$1)) | F37: =IF('AUDIT-Q'!$C34=0,"",COUNTIF('AUDIT-Q'!$C34:$J34,RESULTS!F$1)) | G37: =IF('AUDIT-Q'!$C34=0,"",COUNTIF('AUDIT-Q'!$C34:$J34,RESULTS!G$1)) | H37: =IF('AUDIT-Q'!$C34=0,"",COUNTIF('AUDIT-Q'!$C34:$J34,RESULTS!H$1))
A38: 4.4 | B38: If Welding of New Pipe to Existing Pipe Required, are instructions noted in the Job Pack to perform NDE at the proposed tie-in point prior to beginning mechanical work? Is a note about requirement to perform NDE included on the ISO drawing? | C38: =IF('AUDIT-Q'!$C35=0,"",COUNTIF('AUDIT-Q'!$C35:$J35,RESULTS!C$1)) | D38: =IF('AUDIT-Q'!$C35=0,"",COUNTIF('AUDIT-Q'!$C35:$J35,RESULTS!D$1)) | E38: =IF('AUDIT-Q'!$C35=0,"",COUNTIF('AUDIT-Q'!$C35:$J35,RESULTS!E$1)) | F38: =IF('AUDIT-Q'!$C35=0,"",COUNTIF('AUDIT-Q'!$C35:$J35,RESULTS!F$1)) | G38: =IF('AUDIT-Q'!$C35=0,"",COUNTIF('AUDIT-Q'!$C35:$J35,RESULTS!G$1)) | H38: =IF('AUDIT-Q'!$C35=0,"",COUNTIF('AUDIT-Q'!$C35:$J35,RESULTS!H$1))
A39: 5 | B39: Golden Weld (Closure Weld) | C39: =SUM(C40:C46) -> 0 | D39: =SUM(D40:D46) -> 0 | E39: =SUM(E40:E46) -> 0 | F39: =SUM(F40:F46) -> 0 | G39: =SUM(G40:G46) -> 0 | H39: =SUM(H40:H46) -> 0
B40: Are the following documents attached to the Request? | C40: =IF('AUDIT-Q'!$C37=0,"",COUNTIF('AUDIT-Q'!$C37:$J37,RESULTS!C$1)) | D40: =IF('AUDIT-Q'!$C37=0,"",COUNTIF('AUDIT-Q'!$C37:$J37,RESULTS!D$1)) | E40: =IF('AUDIT-Q'!$C37=0,"",COUNTIF('AUDIT-Q'!$C37:$J37,RESULTS!E$1)) | F40: =IF('AUDIT-Q'!$C37=0,"",COUNTIF('AUDIT-Q'!$C37:$J37,RESULTS!F$1)) | G40: =IF('AUDIT-Q'!$C37=0,"",COUNTIF('AUDIT-Q'!$C37:$J37,RESULTS!G$1)) | H40: =IF('AUDIT-Q'!$C37=0,"",COUNTIF('AUDIT-Q'!$C37:$J37,RESULTS!H$1))
...

Sheet List of JPs
B1: FE LOG# | C1: JDE EWR# | D1: Title | E1: Position | F1: Group | G1: AFE | H1: Auditors | I1: Date | J1: Audit Findings (Summary for Review Meeting)
A2: EXAMPLE | B2: 14-017 | C2: 568591 | D2: KTL2.1, U500, Pipeline replacement from ЕА-501 | E2: dent9 | F2: KTL TA | G2: MEJ/OPEX | H2: Daniyar Z./Jim W. | I2: 42156 | J2: Nothing Significant to Report
A3: 1
A4: 2
A5: 3
A6: 4
A7: 5
A8: 6
A9: 7
A10: 8
A11: 9
A12: 10
A13: 11
A14: 12
... A33: 31
